# 10.1-异常机制-错误处理

## 一 Koa 中的异常处理

### 1.0 说明

这里以 Koa 为例，因为 Koa 是下一代 Web 框架，非常适合作为大型框架的基础框架。

错误处理是开发中最常见的需求之一，在后端，错误处理的核心目标是让服务端不会因为一些未捕获错误而死去。

### 1.1 Koa 抛出错误

Koa 默认提供了 throw() 方法抛出错误：

```js
const Koa = require('koa')
const Router = require('koa-router')

const app = new Koa()
const router = new Router()

router.get('/error/serverErr', async (ctx, next) => {
  ctx.throw(500) // 错误：Internal Server Error
})

router.get('/error/serverErr2', async (ctx, next) => {
  ctx.throw(501) // 错误：Not Implemented
})

router.get('/error/sourceErr2', async (ctx, next) => {
  ctx.throw(400) // 错误：Bad Request
})

router.get('/error/sourceErr', async (ctx, next) => {
  ctx.throw(404) // 错误：NotFound
})

app.use(router.routes())
app.use(router.allowedMethods()) //根据 ctx.status 设置响应头

app.listen(3000)
```

值得注意的是，如果将 ctx.response.status 设置成对应的状态码，效果跟 ctx.throw() 是一样的：

```js
router.get('/error/sourceErr', async (ctx, next) => {
  ctx.status = 404
  ctx.body = 'Page Not Found'
})
```

### 1.2 错误处理事件

错误处理事件 error 可以捕获全局中的错误：

```js
router.get('/error/onErr', async (ctx, next) => {
  throw '数据库连接失败'
})

app.on('error', async (err, ctx) => {
  console.log('捕获到错误：', err)
  // 都不会触发
  // ctx.status = 404
  // ctx.body = '发生了异常'
})
```

如果错误被 try...catch 捕获，就不会触发 error 事件。这时，必须调用 ctx.app.emit()，手动释放 error 事件，才能让监听函数生效，而且此时也可以在 error 事件函数中对 ctx 进行处理了：

```js
router.get('/error/onErr', async (ctx, next) => {
  try {
    throw new Error('数据库连接失败')
  } catch (e) {
    ctx.app.emit('error', e, ctx)
  }
})

app.on('error', async (err, ctx) => {
  console.log('ctx:', ctx)
  console.log('捕获到错误：', err)

  // 现在会触发不会触发
  ctx.status = 500
  ctx.body = { msg: err.message }
})
```

## 二 错误处理实践

### 2.1 企业中的错误处理

在企业的 MVC 分层模型中，经常会在 Controller 层进行错误处理：如参数校验错误将错误返回给前端。

但是如果是 Service 发生的错误呢？这里有两种选择：

- Service 层通过自定义错误码，向 Controller 层传递自定义错误码，在 Controller 层进行正常处理
- Service 层的错误向上抛出，在 Controller 层进行 catch 处理

### 2.2 错误处理中间件

可以利用 Koa 的中间件机制，将上述两种做法进行一定的结合，作为更好的错误处理方式。

首先假设错误的返回给客户端的方式是：

```js
{
    errCode: 10000,
    errMsg: 'Server Err'
}
```

可以定义一个 http 异常，由中间件进行全局错误拦截：

```js
const Koa = require('koa')
const Router = require('koa-router')

const app = new Koa()
const router = new Router()

class HttpException extends Error {
  constructor(code = 10000, msg) {
    super()
    this.errCode = code
    this.errMsg = msg || '服务器异常'
  }
}

async function httpErrorMiddleware(ctx, next) {
  try {
    await next()
  } catch (e) {
    if (e instanceof HttpException) {
      ctx.status = 200
      ctx.body = {
        errCode: e.errCode,
        errMsg: e.errMsg,
        requestUrl: `${ctx.method} ${ctx.path}`,
      }
    } else {
      ctx.status = 500
      ctx.body = {
        errCode: 11000,
        errMsg: e.message || '未知服务错误',
        requestUrl: `${ctx.method} ${ctx.path}`,
      }
    }
  }
}

router.get('/error/paramErr', httpErrorMiddleware, (ctx, next) => {
  throw new HttpException(10001, '参数不合法')
})

router.get('/error/notFoundErr', httpErrorMiddleware, (ctx, next) => {
  throw new HttpException(10004, '资源不存在')
})

router.get('/error/sourceErr', httpErrorMiddleware, (ctx, next) => {
  ctx.throw(400)
})

app.use(router.routes())
app.use(router.allowedMethods()) //根据 ctx.status 设置响应头

app.listen(3000)
```

### 2.3 错误处理优化 - 最终版

显然上述的错误处理在自定义上无法满足我们的需要，写起来也较为繁琐。

首先我们会需要自定义更多的错误，这些错通通过继承关系实现即可，此外为了简化导出的不同类型异常数目过多，可以通过工厂函数形式导出：

```js
class HttpException extends Error {
  constructor(code = 10000, msg) {
    super()
    this.errCode = code
    this.errMsg = msg || '服务器异常'
  }
}

class ParamException extends HttpException {
  constructor(msg) {
    super()
    this.errCode = 10001
    this.errMsg = msg || '参数不合法'
  }
}

class NotFountException extends HttpException {
  constructor(msg) {
    super()
    this.errCode = 10004
    this.errMsg = msg || '资源未找到'
    this.status = 404
  }
}

class ForbiddenException extends HttpException {
  constructor(msg) {
    super()
    this.errCode = 10005
    this.errMsg = msg || '没有资源权限'
    this.status = 403
  }
}

// 直接导出会导致导入错误时过于繁琐
// module.exports = {
//     HttpException,ParamException,NotFountException,ForbiddenException
// }

// 在传参时无需记住字符串
const HttpCode = {
  ParamException: 'ParamException',
  NotFountException: 'NotFountException',
  ForbiddenException: 'ForbiddenException',
}

// 根据传入的名字创建对象
function createHttpException(exceptionStr = 'HttpException', msg = '') {
  return eval(`new ${exceptionStr}('${msg}')`)
}

module.exports = { HttpCode, HttpException, createHttpException }
```

中间件不需要有太多变化，路由中使用：

```js
const Koa = require('koa')
const Router = require('koa-router')
const httpErrorMiddleware = require('./middleware/httpErrorMiddleware')
const { HttpCode, createHttpException } = require('./common/HttpException')

const app = new Koa()
const router = new Router()

app.use(httpErrorMiddleware)

// 自定义错误数据
router.get('/error/paramErr', (ctx, next) => {
  throw createHttpException(HttpCode.ParamException, 'uid 不合法')
})

// 使用默认设置
router.get('/error/notFoundErr', (ctx, next) => {
  throw createHttpException(HttpCode.NotFountException)
})

// 未定义的错误捕获
router.get('/error/sourceErr', (ctx, next) => {
  ctx.throw(400) // 错误：Bad Request
})

app.use(router.routes())
app.use(router.allowedMethods()) //根据 ctx.status 设置响应头

app.listen(3000)
```
