# 06.3-异步编程-Promise 其他设置

## 一 非重入期约方法

当期约进入落定状态时，与该状态相关的处理程序仅仅会被排期，而非立即执行。跟在添加这个处理程序的代码之后的同步代码一定会在处理程序之前先执行。即使期约一开始就是与附加处理程序关联的状态，执行顺序也是这样的。这个特性由 JavaScript 运行时保证，被称为“非重入”（ non-reentrancy）特性。下面的例子演示了这个特性：

```js
// 创建解决的期约
let p = Promise.resolve()
// 添加解决处理程序
// 直觉上，这个处理程序会等期约一解决就执行
p.then(() => console.log('onResolved handler'))
// 同步输出，证明 then()已经返回
console.log('then() returns')
// 实际的输出：
// then() returns
// onResolved handler
```

在这个例子中，在一个解决期约上调用 then()会把 onResolved 处理程序推进消息队列。但这个处理程序在当前线程上的同步代码执行完成前不会执行。因此，跟在 then()后面的同步代码一定先于处理程序执行。

先添加处理程序后解决期约也是一样的。如果添加处理程序后，同步代码才改变期约状态，那么处理程序仍然会基于该状态变化表现出非重入特性。下面的例子展示了即使先添加了 onResolved 处理程序，再同步调用 resolve()，处理程序也不会进入同步线程执行：

```js
let synchronousResolve
// 创建一个期约并将解决函数保存在一个局部变量中
let p = new Promise((resolve) => {
  synchronousResolve = function () {
    console.log('1: invoking resolve()')
    resolve()
    console.log('2: resolve() returns')
  }
})
p.then(() => console.log('4: then() handler executes'))
synchronousResolve()
console.log('3: synchronousResolve() returns')

// 实际的输出：
// 1: invoking resolve()
// 2: resolve() returns
// 3: synchronousResolve() returns
// 4: then() handler executes
```

非重入适用于 onResolved/onRejected 处理程序、 catch()处理程序和 finally()处理程序。下面的例子演示了这些处理程序都只能异步执行：

```js
let p1 = Promise.resolve()
p1.then(() => console.log('p1.then() onResolved'))
console.log('p1.then() returns')
let p2 = Promise.reject()
p2.then(null, () => console.log('p2.then() onRejected'))
console.log('p2.then() returns')
let p3 = Promise.reject()
p3.catch(() => console.log('p3.catch() onRejected'))
console.log('p3.catch() returns')
let p4 = Promise.resolve()
p4.finally(() => console.log('p4.finally() onFinally'))
console.log('p4.finally() returns')
// p1.then() returns
// p2.then() returns
// p3.catch() returns
// p4.finally() returns
// p1.then() onResolved
// p2.then() onRejected
// p3.catch() onRejected
// p4.finally() onFinally
```

## 二 邻近处理程序的执行顺序

如果给期约添加了多个处理程序，当期约状态变化时，相关处理程序会按照添加它们的顺序依次执行。无论是 then()、 catch()还是 finally()添加的处理程序都是如此：

```js
let p1 = Promise.resolve()
let p2 = Promise.reject()
p1.then(() => setTimeout(console.log, 0, 1))
p1.then(() => setTimeout(console.log, 0, 2))
// 1
// 2
p2.then(null, () => setTimeout(console.log, 0, 3))
p2.then(null, () => setTimeout(console.log, 0, 4))
// 3
// 4
p2.catch(() => setTimeout(console.log, 0, 5))
p2.catch(() => setTimeout(console.log, 0, 6))
// 5
// 6
p1.finally(() => setTimeout(console.log, 0, 7))
p1.finally(() => setTimeout(console.log, 0, 8))
// 7
// 8
```

## 三 传递解决值和拒绝理由

到了落定状态后，期约会提供其解决值（如果兑现）或其拒绝理由（如果拒绝）给相关状态的处理程序。拿到返回值后，就可以进一步对这个值进行操作。比如，第一次网络请求返回的 JSON 是发送第二次请求必需的数据，那么第一次请求返回的值就应该传给 onResolved 处理程序继续处理。当然，失败的网络请求也应该把 HTTP 状态码传给 onRejected 处理程序。

在执行函数中，解决的值和拒绝的理由是分别作为 resolve()和 reject()的第一个参数往后传的。然后，这些值又会传给它们各自的处理程序，作为 onResolved 或 onRejected 处理程序的唯一参数。下面的例子展示了上述传递过程：

```js
let p1 = new Promise((resolve, reject) => resolve('foo'))
p1.then((value) => console.log(value)) // foo
let p2 = new Promise((resolve, reject) => reject('bar'))
p2.catch((reason) => console.log(reason)) // bar
```

Promise.resolve()和 Promise.reject()在被调用时就会接收解决值和拒绝理由。同样地，它们返回的期约也会像执行器一样把这些值传给 onResolved 或 onRejected 处理程序：

```js
let p1 = Promise.resolve('foo')
p1.then((value) => console.log(value)) // foo
let p2 = Promise.reject('bar')
p2.catch((reason) => console.log(reason)) // bar
```

## 四 拒绝期约与拒绝错误处理

拒绝期约类似于 throw()表达式，因为它们都代表一种程序状态，即需要中断或者特殊处理。在期约的执行函数或处理程序中抛出错误会导致拒绝，对应的错误对象会成为拒绝的理由。因此以下这些期约都会以一个错误对象为由被拒绝：

```js
let p1 = new Promise((resolve, reject) => reject(Error('foo')))
let p2 = new Promise((resolve, reject) => {
  throw Error('foo')
})
let p3 = Promise.resolve().then(() => {
  throw Error('foo')
})
let p4 = Promise.reject(Error('foo'))
setTimeout(console.log, 0, p1) // Promise <rejected>: Error: foo
setTimeout(console.log, 0, p2) // Promise <rejected>: Error: foo
setTimeout(console.log, 0, p3) // Promise <rejected>: Error: foo
setTimeout(console.log, 0, p4) // Promise <rejected>: Error: foo
// 也会抛出 4 个未捕获错误
```

期约可以以任何理由拒绝，包括 undefined，但最好统一使用错误对象。这样做主要是因为创建错误对象可以让浏览器捕获错误对象中的栈追踪信息，而这些信息对调试是非常关键的。例如，前面例子中抛出的 4 个错误的栈追踪信息如下：

```txt
Uncaught (in promise) Error: foo
at Promise (test.html:5)
at new Promise (<anonymous>)
at test.html:5
Uncaught (in promise) Error: foo
at Promise (test.html:6)
at new Promise (<anonymous>)
at test.html:6
Uncaught (in promise) Error: foo
at test.html:8
Uncaught (in promise) Error: foo
at Promise.resolve.then (test.html:7)
```

所有错误都是异步抛出且未处理的，通过错误对象捕获的栈追踪信息展示了错误发生的路径。注意错误的顺序： Promise.resolve().then()的错误最后才出现，这是因为它需要在运行时消息队列中添加处理程序；也就是说，在最终抛出未捕获错误之前它还会创建另一个期约。

这个例子同样揭示了异步错误有意思的副作用。正常情况下，在通过 throw()关键字抛出错误时，JavaScript 运行时的错误处理机制会停止执行抛出错误之后的任何指令：

```js
throw Error('foo')
console.log('bar') // 这一行不会执行
// Uncaught Error: foo
```

但是，在期约中抛出错误时，因为错误实际上是从消息队列中异步抛出的，所以并不会阻止运行时继续执行同步指令：

```js
Promise.reject(Error('foo'))
console.log('bar')
// bar
// Uncaught (in promise) Error: foo
```

如本章前面的 Promise.reject()示例所示，异步错误只能通过异步的 onRejected 处理程序捕获：

```js
// 正确
Promise.reject(Error('foo')).catch((e) => {})
// 不正确
try {
  Promise.reject(Error('foo'))
} catch (e) {}
```

这不包括捕获执行函数中的错误，在解决或拒绝期约之前，仍然可以使用 try/catch 在执行函数中捕获错误：

```js
let p = new Promise((resolve, reject) => {
  try {
    throw Error('foo')
  } catch (e) {}
  resolve('bar')
})
setTimeout(console.log, 0, p) // Promise <resolved>: bar
```

then()和 catch()的 onRejected 处理程序在语义上相当于 try/catch。出发点都是捕获错误之后将其隔离，同时不影响正常逻辑执行。为此， onRejected 处理程序的任务应该是在捕获异步错误之后返回一个解决的期约。下面的例子中对比了同步错误处理与异步错误处理：

```js
console.log('begin synchronous execution')
try {
  throw Error('foo')
} catch (e) {
  console.log('caught error', e)
}
console.log('continue synchronous execution')
// begin synchronous execution
// caught error Error: foo
// continue synchronous execution
new Promise((resolve, reject) => {
  console.log('begin asynchronous execution')
  reject(Error('bar'))
})
  .catch((e) => {
    console.log('caught error', e)
  })
  .then(() => {
    console.log('continue asynchronous execution')
  })
// begin asynchronous execution
// caught error Error: bar
// continue asynchronous execution
```

## 五 期约取消

ES6 的期约不支持取消，可以利用令牌机制取消：

```html
<button id="start">Start</button>
<button id="cancel">Cancel</button>
<script>
  class CancelToken {
    constructor(cancelFn) {
      this.promise = new Promise((resolve, reject) => {
        cancelFn(() => {
          setTimeout(console.log, 0, 'delay cancelled')
          resolve()
        })
      })
    }
  }
  const startButton = document.querySelector('#start')
  const cancelButton = document.querySelector('#cancel')
  function cancellableDelayedResolve(delay) {
    setTimeout(console.log, 0, 'set delay')
    return new Promise((resolve, reject) => {
      const id = setTimeout(() => {
        setTimeout(console.log, 0, 'delayed resolve')
        resolve()
      }, delay)
      const cancelToken = new CancelToken((cancelCallback) =>
        cancelButton.addEventListener('click', cancelCallback)
      )
      cancelToken.promise.then(() => clearTimeout(id))
    })
  }
  startButton.addEventListener('click', () => cancellableDelayedResolve(1000))
</script>
```

每次单击“Start”按钮都会开始计时，并实例化一个新的 CancelToken 的实例。此时，“Cancel”按钮一旦被点击，就会触发令牌实例中的期约解决。而解决之后，单击“Start”按钮设置的超时也会被取消。

## 六 期约的进度通知

执行中的期约可能会有不少离散的“阶段”，在最终解决之前必须依次经过。某些情况下，监控期约的执行进度会很有用。 ECMAScript 6 期约并不支持进度追踪，但是可以通过扩展来实现。

一种实现方式是扩展 Promise 类，为它添加 notify()方法：

```js
class TrackablePromise extends Promise {
  constructor(executor) {
    const notifyHandlers = []
    super((resolve, reject) => {
      return executor(resolve, reject, (status) => {
        notifyHandlers.map((handler) => handler(status))
      })
    })
    this.notifyHandlers = notifyHandlers
  }
  notify(notifyHandler) {
    this.notifyHandlers.push(notifyHandler)
    return this
  }
}

let p = new TrackablePromise((resolve, reject, notify) => {
  function countdown(x) {
    if (x > 0) {
      notify(`${20 * x}% remaining`)
      setTimeout(() => countdown(x - 1), 1000)
    } else {
      resolve()
    }
  }
  countdown(5)
})
```

这个期约会连续 5 次递归地设置 1000 毫秒的超时。每个超时回调都会调用 notify()并传入状态值。假设通知处理程序简单地这样写：

```js
let p = new TrackablePromise((resolve, reject, notify) => {
  function countdown(x) {
    if (x > 0) {
      notify(`${20 * x}% remaining`)
      setTimeout(() => countdown(x - 1), 1000)
    } else {
      resolve()
    }
  }
  countdown(5)
})
p.notify((x) => setTimeout(console.log, 0, 'progress:', x))
p.then(() => setTimeout(console.log, 0, 'completed'))
// （约 1 秒后） 80% remaining
// （约 2 秒后） 60% remaining
// （约 3 秒后） 40% remaining
// （约 4 秒后） 20% remaining
// （约 5 秒后） completed
```

notify()函数会返回期约，所以可以连缀调用，连续添加处理程序。多个处理程序会针对收到的
每条消息分别执行一遍，如下所示：

```js
p.notify((x) => setTimeout(console.log, 0, 'a:', x)).notify((x) =>
  setTimeout(console.log, 0, 'b:', x)
)
p.then(() => setTimeout(console.log, 0, 'completed'))
// （约 1 秒后） a: 80% remaining
// （约 1 秒后） b: 80% remaining
// （约 2 秒后） a: 60% remaining
// （约 2 秒后） b: 60% remaining
// （约 3 秒后） a: 40% remaining
// （约 3 秒后） b: 40% remaining
// （约 4 秒后） a: 20% remaining
// （约 4 秒后） b: 20% remaining
// （约 5 秒后） completed
```

以上只是简单实现了通知报告进度。
